Workbook

Sheet Tổng quan
A1: Đề tài: Kho dữ liệu khí tượng đa nguồn – dự báo khả năng mưa miền Bắc
A2: Bảng tổng hợp tiến độ nhóm 3 người (tự cập nhật từ sheet "Theo dõi công việc")
B4: Mã | C4: Họ tên (điền) | D4: Vai trò | E4: Số việc | F4: Hoàn thành | G4: Đang làm | H4: Bị chặn | I4: Quá hạn | J4: % tiến độ
B5: N1 | C5: Người 1 | D5: Data Engineer | E5: =COUNTIF('Theo dõi công việc'!$G$5:$G$200,B5) -> 13 | F5: =COUNTIFS('Theo dõi công việc'!$G$5:$G$200,B5,'Theo dõi công việc'!$M$5:$M$200,"Hoàn thành") -> 0 | G5: =COUNTIFS('Theo dõi công việc'!$G$5:$G$200,B5,'Theo dõi công việc'!$M$5:$M$200,"Đang làm") -> 0 | H5: =COUNTIFS('Theo dõi công việc'!$G$5:$G$200,B5,'Theo dõi công việc'!$M$5:$M$200,"Bị chặn") -> 0 | I5: =COUNTIFS('Theo dõi công việc'!$G$5:$G$200,B5,'Theo dõi công việc'!$L$5:$L$200,"<"&TODAY(),'Theo dõi công việc'!$M$5:$M$200,"<>Hoàn thành") -> 0 | J5: =IFERROR(AVERAGEIF('Theo dõi công việc'!$G$5:$G$200,B5,'Theo dõi công việc'!$N$5:$N$200),0) -> 0
B6: N2 | C6: Người 2 | D6: DW & BI | E6: =COUNTIF('Theo dõi công việc'!$G$5:$G$200,B6) -> 12 | F6: =COUNTIFS('Theo dõi công việc'!$G$5:$G$200,B6,'Theo dõi công việc'!$M$5:$M$200,"Hoàn thành") -> 0 | G6: =COUNTIFS('Theo dõi công việc'!$G$5:$G$200,B6,'Theo dõi công việc'!$M$5:$M$200,"Đang làm") -> 0 | H6: =COUNTIFS('Theo dõi công việc'!$G$5:$G$200,B6,'Theo dõi công việc'!$M$5:$M$200,"Bị chặn") -> 0 | I6: =COUNTIFS('Theo dõi công việc'!$G$5:$G$200,B6,'Theo dõi công việc'!$L$5:$L$200,"<"&TODAY(),'Theo dõi công việc'!$M$5:$M$200,"<>Hoàn thành") -> 0 | J6: =IFERROR(AVERAGEIF('Theo dõi công việc'!$G$5:$G$200,B6,'Theo dõi công việc'!$N$5:$N$200),0) -> 0
B7: N3 | C7: Người 3 | D7: Data Mining | E7: =COUNTIF('Theo dõi công việc'!$G$5:$G$200,B7) -> 12 | F7: =COUNTIFS('Theo dõi công việc'!$G$5:$G$200,B7,'Theo dõi công việc'!$M$5:$M$200,"Hoàn thành") -> 0 | G7: =COUNTIFS('Theo dõi công việc'!$G$5:$G$200,B7,'Theo dõi công việc'!$M$5:$M$200,"Đang làm") -> 0 | H7: =COUNTIFS('Theo dõi công việc'!$G$5:$G$200,B7,'Theo dõi công việc'!$M$5:$M$200,"Bị chặn") -> 0 | I7: =COUNTIFS('Theo dõi công việc'!$G$5:$G$200,B7,'Theo dõi công việc'!$L$5:$L$200,"<"&TODAY(),'Theo dõi công việc'!$M$5:$M$200,"<>Hoàn thành") -> 0 | J7: =IFERROR(AVERAGEIF('Theo dõi công việc'!$G$5:$G$200,B7,'Theo dõi công việc'!$N$5:$N$200),0) -> 0
B8: Cả nhóm | C8: Cả nhóm | D8: Việc chung | E8: =COUNTIF('Theo dõi công việc'!$G$5:$G$200,B8) -> 3 | F8: =COUNTIFS('Theo dõi công việc'!$G$5:$G$200,B8,'Theo dõi công việc'!$M$5:$M$200,"Hoàn thành") -> 0 | G8: =COUNTIFS('Theo dõi công việc'!$G$5:$G$200,B8,'Theo dõi công việc'!$M$5:$M$200,"Đang làm") -> 0 | H8: =COUNTIFS('Theo dõi công việc'!$G$5:$G$200,B8,'Theo dõi công việc'!$M$5:$M$200,"Bị chặn") -> 0 | I8: =COUNTIFS('Theo dõi công việc'!$G$5:$G$200,B8,'Theo dõi công việc'!$L$5:$L$200,"<"&TODAY(),'Theo dõi công việc'!$M$5:$M$200,"<>Hoàn thành") -> 0 | J8: =IFERROR(AVERAGEIF('Theo dõi công việc'!$G$5:$G$200,B8,'Theo dõi công việc'!$N$5:$N$200),0) -> 0
B9: Tổng | E9: =SUM(E5:E8) -> 40 | F9: =SUM(F5:F8) -> 0 | G9: =SUM(G5:G8) -> 0 | H9: =SUM(H5:H8) -> 0 | I9: =SUM(I5:I8) -> 0 | J9: =IFERROR(AVERAGE('Theo dõi công việc'!$N$5:$N$200),0) -> 0
B11: Ngày bắt đầu tuần 1 (thứ Hai): | E11: 46307 | F11: Giả định: thứ Hai tuần sau. Sửa ô này theo lịch học thực tế, mọi ngày bắt đầu/hạn chót sẽ tự đổi.
B13: Tiến độ theo tuần
B14: Tuần | C14: Từ ngày | D14: Đến ngày | E14: Việc hết hạn trong tuần | F14: Đã hoàn thành | G14: % hoàn thành
B15: 1 | C15: =$E$11+(B15-1)*7 -> 46307 | D15: =C15+4 -> 46311 | E15: =COUNTIF('Theo dõi công việc'!$C$5:$C$200,B15) -> 7 | F15: =COUNTIFS('Theo dõi công việc'!$C$5:$C$200,B15,'Theo dõi công việc'!$M$5:$M$200,"Hoàn thành") -> 0 | G15: =IF(E15=0,"-",F15/E15) -> 0
B16: 2 | C16: =$E$11+(B16-1)*7 -> 46314 | D16: =C16+4 -> 46318 | E16: =COUNTIF('Theo dõi công việc'!$C$5:$C$200,B16) -> 0 | F16: =COUNTIFS('Theo dõi công việc'!$C$5:$C$200,B16,'Theo dõi công việc'!$M$5:$M$200,"Hoàn thành") -> 0 | G16: =IF(E16=0,"-",F16/E16) -> -
B17: 3 | C17: =$E$11+(B17-1)*7 -> 46321 | D17: =C17+4 -> 46325 | E17: =COUNTIF('Theo dõi công việc'!$C$5:$C$200,B17) -> 8 | F17: =COUNTIFS('Theo dõi công việc'!$C$5:$C$200,B17,'Theo dõi công việc'!$M$5:$M$200,"Hoàn thành") -> 0 | G17: =IF(E17=0,"-",F17/E17) -> 0
B18: 4 | C18: =$E$11+(B18-1)*7 -> 46328 | D18: =C18+4 -> 46332 | E18: =COUNTIF('Theo dõi công việc'!$C$5:$C$200,B18) -> 0 | F18: =COUNTIFS('Theo dõi công việc'!$C$5:$C$200,B18,'Theo dõi công việc'!$M$5:$M$200,"Hoàn thành") -> 0 | G18: =IF(E18=0,"-",F18/E18) -> -
B19: 5 | C19: =$E$11+(B19-1)*7 -> 46335 | D19: =C19+4 -> 46339 | E19: =COUNTIF('Theo dõi công việc'!$C$5:$C$200,B19) -> 8 | F19: =COUNTIFS('Theo dõi công việc'!$C$5:$C$200,B19,'Theo dõi công việc'!$M$5:$M$200,"Hoàn thành") -> 0 | G19: =IF(E19=0,"-",F19/E19) -> 0
B20: 6 | C20: =$E$11+(B20-1)*7 -> 46342 | D20: =C20+4 -> 46346 | E20: =COUNTIF('Theo dõi công việc'!$C$5:$C$200,B20) -> 0 | F20: =COUNTIFS('Theo dõi công việc'!$C$5:$C$200,B20,'Theo dõi công việc'!$M$5:$M$200,"Hoàn thành") -> 0 | G20: =IF(E20=0,"-",F20/E20) -> -
B21: 7 | C21: =$E$11+(B21-1)*7 -> 46349 | D21: =C21+4 -> 46353 | E21: =COUNTIF('Theo dõi công việc'!$C$5:$C$200,B21) -> 7 | F21: =COUNTIFS('Theo dõi công việc'!$C$5:$C$200,B21,'Theo dõi công việc'!$M$5:$M$200,"Hoàn thành") -> 0 | G21: =IF(E21=0,"-",F21/E21) -> 0
B22: 8 | C22: =$E$11+(B22-1)*7 -> 46356 | D22: =C22+4 -> 46360 | E22: =COUNTIF('Theo dõi công việc'!$C$5:$C$200,B22) -> 3 | F22: =COUNTIFS('Theo dõi công việc'!$C$5:$C$200,B22,'Theo dõi công việc'!$M$5:$M$200,"Hoàn thành") -> 0 | G22: =IF(E22=0,"-",F22/E22) -> 0
B23: 9 | C23: =$E$11+(B23-1)*7 -> 46363 | D23: =C23+4 -> 46367 | E23: =COUNTIF('Theo dõi công việc'!$C$5:$C$200,B23) -> 3 | F23: =COUNTIFS('Theo dõi công việc'!$C$5:$C$200,B23,'Theo dõi công việc'!$M$5:$M$200,"Hoàn thành") -> 0 | G23: =IF(E23=0,"-",F23/E23) -> 0
B24: 10 | C24: =$E$11+(B24-1)*7 -> 46370 | D24: =C24+4 -> 46374 | E24: =COUNTIF('Theo dõi công việc'!$C$5:$C$200,B24) -> 4 | F24: =COUNTIFS('Theo dõi công việc'!$C$5:$C$200,B24,'Theo dõi công việc'!$M$5:$M$200,"Hoàn thành") -> 0 | G24: =IF(E24=0,"-",F24/E24) -> 0
B27: Hướng dẫn
B28: Ô nền vàng | C28: là ô cần điền/cập nhật: họ tên thành viên, ngày bắt đầu tuần 1, trạng thái, % hoàn thành, ghi chú.
B29: Ô nền trắng | C29: là công thức tự tính, không cần sửa.
B30: Trạng thái | C30: chọn từ danh sách: Chưa bắt đầu / Đang làm / Hoàn thành / Bị chặn. Khi chọn Hoàn thành, đặt % = 100%.
B31: Mã phụ trách | C31: N1, N2, N3 hoặc Cả nhóm; tên người tự hiện theo bảng thành viên ở trên.
B32: Quá hạn | C32: là việc có hạn chót trước hôm nay mà chưa Hoàn thành (dòng tô đỏ nhạt).
B33: Thêm việc | C33: điền tiếp ở cuối sheet Theo dõi công việc (tối đa dòng 200), copy công thức cột H, K, L từ dòng trên.

Sheet Theo dõi công việc
A1: Theo dõi công việc
A2: Ô nền vàng: cập nhật trạng thái, % hoàn thành và ghi chú. Ngày tự tính từ 'Tổng quan'!E11.
A4: ID | B4: Tuần bắt đầu | C4: Tuần kết thúc | D4: Giai đoạn | E4: Hạng mục | F4: Công việc | G4: Mã phụ trách | H4: Người phụ trách | I4: Hỗ trợ | J4: Đầu ra | K4: Ngày bắt đầu | L4: Hạn chót | M4: Trạng thái | N4: % hoàn thành | O4: Ghi chú
A5: 1 | B5: 1 | C5: 1 | D5: Tuần 1 | E5: Hạ tầng | F5: Dựng Docker Compose (MinIO, Airflow, PostgreSQL), tạo repo Git | G5: N1 | H5: =IF(G5="Cả nhóm","Cả nhóm",IFERROR(INDEX('Tổng quan'!$C$5:$C$7,MATCH(G5,'Tổng quan'!$B$5:$B$7,0)),"")) -> Người 1 | J5: docker-compose.yml chạy được trên máy cả nhóm | K5: ='Tổng quan'!$E$11+(B5-1)*7 -> 46307 | L5: ='Tổng quan'!$E$11+(C5-1)*7+4 -> 46311 | M5: Đang làm | N5: 80 | O5: Compose/Dockerfile build OK; MinIO+Postgres đã chạy. Chưa kiểm chứng webserver/scheduler end-to-end (21/10)
A6: 2 | B6: 1 | C6: 1 | D6: Tuần 1 | E6: Data Lake | F6: Tạo bucket bronze / silver / gold trên MinIO, quy ước đặt tên file | G6: N1 | H6: =IF(G6="Cả nhóm","Cả nhóm",IFERROR(INDEX('Tổng quan'!$C$5:$C$7,MATCH(G6,'Tổng quan'!$B$5:$B$7,0)),"")) -> Người 1 | J6: 3 bucket + quy ước thư mục | K6: ='Tổng quan'!$E$11+(B6-1)*7 -> 46307 | L6: ='Tổng quan'!$E$11+(C6-1)*7+4 -> 46311 | M6: Đang làm | N6: 90 | O6: Đã có 3 bucket và key đúng quy ước. Còn thiếu: Bronze chưa giữ nguyên payload gốc (_pipeline_metadata)
A7: 3 | B7: 1 | C7: 1 | D7: Tuần 1 | E7: Data Warehouse | F7: Phác thảo Star Schema: Fact, Dim, grain | G7: N2 | H7: =IF(G7="Cả nhóm","Cả nhóm",IFERROR(INDEX('Tổng quan'!$C$5:$C$7,MATCH(G7,'Tổng quan'!$B$5:$B$7,0)),"")) -> Người 2 | I7: N3 | J7: Sơ đồ Star Schema bản nháp | K7: ='Tổng quan'!$E$11+(B7-1)*7 -> 46307 | L7: ='Tổng quan'!$E$11+(C7-1)*7+4 -> 46311 | M7: Đang làm | N7: 80 | O7: DDL + sơ đồ star schema (outputs/dfd-weather-20261013). Còn mở: cơ sở lịch, nhiều trạm, prediction
A8: 4 | B8: 1 | C8: 1 | D8: Tuần 1 | E8: Nguồn dữ liệu | F8: Tải GeoJSON địa giới Việt Nam (ranh giới sau sáp nhập 1/7/2025) | G8: N2 | H8: =IF(G8="Cả nhóm","Cả nhóm",IFERROR(INDEX('Tổng quan'!$C$5:$C$7,MATCH(G8,'Tổng quan'!$B$5:$B$7,0)),"")) -> Người 2 | J8: File GeoJSON trong Bronze | K8: ='Tổng quan'!$E$11+(B8-1)*7 -> 46307 | L8: ='Tổng quan'!$E$11+(C8-1)*7+4 -> 46311 | M8: Chưa bắt đầu | N8: 0
A9: 5 | B9: 1 | C9: 1 | D9: Tuần 1 | E9: Nguồn dữ liệu | F9: Đăng ký Copernicus CDS, gửi yêu cầu tải ERA5 (vùng miền Bắc, chỉ các biến cần dùng) | G9: N3 | H9: =IF(G9="Cả nhóm","Cả nhóm",IFERROR(INDEX('Tổng quan'!$C$5:$C$7,MATCH(G9,'Tổng quan'!$B$5:$B$7,0)),"")) -> Người 3 | J9: Yêu cầu tải đã vào hàng đợi | K9: ='Tổng quan'!$E$11+(B9-1)*7 -> 46307 | L9: ='Tổng quan'!$E$11+(C9-1)*7+4 -> 46311 | M9: Chưa bắt đầu | N9: 0
A10: 6 | B10: 1 | C10: 1 | D10: Tuần 1 | E10: Thống nhất | F10: Chốt schema chuẩn tầng Silver: tên cột, đơn vị, timestamp UTC | G10: Cả nhóm | H10: =IF(G10="Cả nhóm","Cả nhóm",IFERROR(INDEX('Tổng quan'!$C$5:$C$7,MATCH(G10,'Tổng quan'!$B$5:$B$7,0)),"")) -> Cả nhóm | J10: File hợp đồng dữ liệu trong repo | K10: ='Tổng quan'!$E$11+(B10-1)*7 -> 46307 | L10: ='Tổng quan'!$E$11+(C10-1)*7+4 -> 46311 | M10: Hoàn thành | N10: 100 | O10: Hoàn thành 21/10: data-contract.md v0.2 (cột/đơn vị/UTC/pressure_type/xử lý trùng/chọn trạm/báo cáo độ phủ). Nhóm xác nhận (qua N1/N2). Còn để mở có ghi rõ: ngưỡng độ phủ tối thiểu
A11: 7 | B11: 1 | C11: 1 | D11: Tuần 1 | E11: Thống nhất | F11: Chốt định nghĩa nhãn RainNext24h: nguồn ưu tiên, ngưỡng mm | G11: Cả nhóm | H11: =IF(G11="Cả nhóm","Cả nhóm",IFERROR(INDEX('Tổng quan'!$C$5:$C$7,MATCH(G11,'Tổng quan'!$B$5:$B$7,0)),"")) -> Cả nhóm | J11: Định nghĩa nhãn ghi trong repo | K11: ='Tổng quan'!$E$11+(B11-1)*7 -> 46307 | L11: ='Tổng quan'!$E$11+(C11-1)*7+4 -> 46311 | M11: Hoàn thành | N11: 100 | O11: Hoàn thành 21/10: rain-label.md v0.2: ngưỡng 1 mm (Yes 50,5% trên 2016–2025), nguồn Open-Meteo, cửa sổ (t,t+24h] đã kiểm chứng, thiếu giờ thì bỏ nhãn. Nhóm xác nhận (qua N1/N2). Còn để mở có ghi rõ: fallback ERA5
A12: 8 | B12: 2 | C12: 3 | D12: Tuần 2–3 | E12: Nguồn dữ liệu | F12: Thu thập Open-Meteo (REST API, JSON) → Bronze | G12: N1 | H12: =IF(G12="Cả nhóm","Cả nhóm",IFERROR(INDEX('Tổng quan'!$C$5:$C$7,MATCH(G12,'Tổng quan'!$B$5:$B$7,0)),"")) -> Người 1 | J12: Dữ liệu 10 năm × 8 địa điểm | K12: ='Tổng quan'!$E$11+(B12-1)*7 -> 46314 | L12: ='Tổng quan'!$E$11+(C12-1)*7+4 -> 46325 | M12: Đang làm | N12: 80 | O12: 21/10: chạy lại trên máy N1/N2: 80/80 file Bronze (8 điểm × 2016–2025), 0 lỗi, 326 s. Còn lệch: Bronze chưa giữ nguyên payload gốc, thiếu manifest
A13: 9 | B13: 2 | C13: 3 | D13: Tuần 2–3 | E13: Nguồn dữ liệu | F13: Thu thập Meteostat / NOAA (CSV/Text) → Bronze | G13: N1 | H13: =IF(G13="Cả nhóm","Cả nhóm",IFERROR(INDEX('Tổng quan'!$C$5:$C$7,MATCH(G13,'Tổng quan'!$B$5:$B$7,0)),"")) -> Người 1 | J13: Dữ liệu trạm thô | K13: ='Tổng quan'!$E$11+(B13-1)*7 -> 46314 | L13: ='Tổng quan'!$E$11+(C13-1)*7+4 -> 46325 | M13: Đang làm | N13: 95 | O13: 21/10: Meteostat chỉ giữ quan trắc thật (HAN). NOAA GHCNh mưa 24h cho 5 điểm (HPH, TNG, LCA, HAN≈Hà Đông, NBI≈Nam Định) 2016–2025: 17.866 ngày, độ phủ 95,9–99,2%, bảng fact_station_daily_rain + view so sánh với Open-Meteo. Chờ nhóm duyệt quy tắc cực trị 300 mm
A14: 10 | B14: 2 | C14: 3 | D14: Tuần 2–3 | E14: ETL – Silver | F14: Làm sạch Open-Meteo và Meteostat → Silver: đơn vị, UTC, trùng lặp, giá trị thiếu | G14: N1 | H14: =IF(G14="Cả nhóm","Cả nhóm",IFERROR(INDEX('Tổng quan'!$C$5:$C$7,MATCH(G14,'Tổng quan'!$B$5:$B$7,0)),"")) -> Người 1 | J14: Bảng Silver theo schema chuẩn | K14: ='Tổng quan'!$E$11+(B14-1)*7 -> 46314 | L14: ='Tổng quan'!$E$11+(C14-1)*7+4 -> 46325 | M14: Đang làm | N14: 90 | O14: 21/10: Silver chạy lại: Open-Meteo 701.376 dòng; Meteostat 87.485 dòng sau khi loại 436.502 giá trị mô hình và 43.575 dòng không có quan trắc; 60 file Silver cũ đã xóa; 0 xung đột, 0 lỗi
A15: 11 | B15: 2 | C15: 3 | D15: Tuần 2–3 | E15: Data Warehouse | F15: DimLocation (tỉnh cũ + tỉnh mới), DimStation, gán trạm theo khoảng cách bằng GeoPandas | G15: N2 | H15: =IF(G15="Cả nhóm","Cả nhóm",IFERROR(INDEX('Tổng quan'!$C$5:$C$7,MATCH(G15,'Tổng quan'!$B$5:$B$7,0)),"")) -> Người 2 | J15: Bảng DimLocation, DimStation | K15: ='Tổng quan'!$E$11+(B15-1)*7 -> 46314 | L15: ='Tổng quan'!$E$11+(C15-1)*7+4 -> 46325 | M15: Đang làm | N15: 60 | O15: 21/10: mã/tọa độ trạm đã xác minh (Meteostat + NOAA ISD), dim_station seed lại 11 trạm. Hợp lệ: HAN 48820, HPH 48826, TNG 48831, LCA 48803. Ánh xạ tỉnh cũ-mới chưa làm
A16: 12 | B16: 2 | C16: 3 | D16: Tuần 2–3 | E16: Data Warehouse | F16: DimDate, DimTime, DimSource | G16: N2 | H16: =IF(G16="Cả nhóm","Cả nhóm",IFERROR(INDEX('Tổng quan'!$C$5:$C$7,MATCH(G16,'Tổng quan'!$B$5:$B$7,0)),"")) -> Người 2 | J16: Các bảng Dim thời gian và nguồn | K16: ='Tổng quan'!$E$11+(B16-1)*7 -> 46314 | L16: ='Tổng quan'!$E$11+(C16-1)*7+4 -> 46325 | M16: Đang làm | N16: 90 | O16: dim_date 4.018 ngày, seed chạy lại ổn; cơ sở lịch UTC+7 cần cả nhóm xác nhận
A17: 13 | B17: 2 | C17: 3 | D17: Tuần 2–3 | E17: Data Warehouse | F17: Viết DDL PostgreSQL cho toàn bộ Star Schema | G17: N2 | H17: =IF(G17="Cả nhóm","Cả nhóm",IFERROR(INDEX('Tổng quan'!$C$5:$C$7,MATCH(G17,'Tổng quan'!$B$5:$B$7,0)),"")) -> Người 2 | J17: Script DDL | K17: ='Tổng quan'!$E$11+(B17-1)*7 -> 46314 | L17: ='Tổng quan'!$E$11+(C17-1)*7+4 -> 46325 | M17: Đang làm | N17: 80 | O17: DDL chạy được trên Postgres; chưa có migration cho DB đã tồn tại
A18: 14 | B18: 2 | C18: 3 | D18: Tuần 2–3 | E18: Nguồn dữ liệu | F18: Đọc ERA5 NetCDF bằng xarray → Bronze | G18: N3 | H18: =IF(G18="Cả nhóm","Cả nhóm",IFERROR(INDEX('Tổng quan'!$C$5:$C$7,MATCH(G18,'Tổng quan'!$B$5:$B$7,0)),"")) -> Người 3 | J18: File NetCDF trong Bronze | K18: ='Tổng quan'!$E$11+(B18-1)*7 -> 46314 | L18: ='Tổng quan'!$E$11+(C18-1)*7+4 -> 46325 | M18: Chưa bắt đầu | N18: 0
A19: 15 | B19: 2 | C19: 3 | D19: Tuần 2–3 | E19: ETL – Silver | F19: ERA5 → Silver: đổi đơn vị (K, m, Pa), tính gió từ u/v, khử cộng dồn mưa, lấy ô lưới gần nhất | G19: N3 | H19: =IF(G19="Cả nhóm","Cả nhóm",IFERROR(INDEX('Tổng quan'!$C$5:$C$7,MATCH(G19,'Tổng quan'!$B$5:$B$7,0)),"")) -> Người 3 | J19: Bảng Silver ERA5 theo schema chuẩn | K19: ='Tổng quan'!$E$11+(B19-1)*7 -> 46314 | L19: ='Tổng quan'!$E$11+(C19-1)*7+4 -> 46325 | M19: Chưa bắt đầu | N19: 0
A20: 16 | B20: 4 | C20: 5 | D20: Tuần 4–5 | E20: ETL – Gold | F20: Gộp Silver → Gold, pivot các nguồn cho ML | G20: N1 | H20: =IF(G20="Cả nhóm","Cả nhóm",IFERROR(INDEX('Tổng quan'!$C$5:$C$7,MATCH(G20,'Tổng quan'!$B$5:$B$7,0)),"")) -> Người 1 | J20: Bảng Gold thống nhất | K20: ='Tổng quan'!$E$11+(B20-1)*7 -> 46328 | L20: ='Tổng quan'!$E$11+(C20-1)*7+4 -> 46339 | M20: Đang làm | N20: 80 | O20: 21/10: Gold 2016–2025 nạp lại trên máy N1/N2: 832.436 dòng, 120 tháng, 0 lỗi, 233 s. Chưa tách bảng pivot cho ML
A21: 17 | B21: 4 | C21: 5 | D21: Tuần 4–5 | E21: Orchestration | F21: DAG Airflow chạy trọn luồng Bronze → Silver → Gold → DW | G21: N1 | H21: =IF(G21="Cả nhóm","Cả nhóm",IFERROR(INDEX('Tổng quan'!$C$5:$C$7,MATCH(G21,'Tổng quan'!$B$5:$B$7,0)),"")) -> Người 1 | I21: N2 | J21: DAG chạy thành công | K21: ='Tổng quan'!$E$11+(B21-1)*7 -> 46328 | L21: ='Tổng quan'!$E$11+(C21-1)*7+4 -> 46339 | M21: Chưa bắt đầu | N21: 0
A22: 18 | B22: 4 | C22: 5 | D22: Tuần 4–5 | E22: Data Warehouse | F22: Nạp FactWeatherObservation với khóa thay thế | G22: N2 | H22: =IF(G22="Cả nhóm","Cả nhóm",IFERROR(INDEX('Tổng quan'!$C$5:$C$7,MATCH(G22,'Tổng quan'!$B$5:$B$7,0)),"")) -> Người 2 | J22: Kho dữ liệu đủ 10 năm | K22: ='Tổng quan'!$E$11+(B22-1)*7 -> 46328 | L22: ='Tổng quan'!$E$11+(C22-1)*7+4 -> 46339 | M22: Đang làm | N22: 95 | O22: 21/10: DW sạch: 788.861 dòng (Open-Meteo 701.376 + Meteostat HAN 87.485), 0 trùng khóa; rút dòng sai đã kiểm chứng trên dữ liệu thật; chạy lại 2024 không đổi số liệu. Lần nạp cuối chậm (3.493 s, máy có thể đã ngủ). Bản 994.145 dòng trên máy bacnx đã lỗi thời
A23: 19 | B23: 4 | C23: 5 | D23: Tuần 4–5 | E23: OLAP | F23: Viết view OLAP: roll-up ngày/tháng/năm, theo tỉnh, theo nguồn | G23: N2 | H23: =IF(G23="Cả nhóm","Cả nhóm",IFERROR(INDEX('Tổng quan'!$C$5:$C$7,MATCH(G23,'Tổng quan'!$B$5:$B$7,0)),"")) -> Người 2 | J23: Các view SQL | K23: ='Tổng quan'!$E$11+(B23-1)*7 -> 46328 | L23: ='Tổng quan'!$E$11+(C23-1)*7+4 -> 46339 | M23: Đang làm | N23: 90 | O23: 21/10: sql/02_olap_views.sql (6 view giờ/ngày/tháng/năm/độ phủ), ngày mưa ≥1 mm, ngày nóng ≥35 °C; đối soát giờ→ngày→tháng→năm khớp 0 chênh trên 788.861 dòng; 3 test tích hợp. Chưa dùng trong Power BI
A24: 20 | B24: 4 | C24: 5 | D24: Tuần 4–5 | E24: BI | F24: Dashboard Power BI bản 1 | G24: N2 | H24: =IF(G24="Cả nhóm","Cả nhóm",IFERROR(INDEX('Tổng quan'!$C$5:$C$7,MATCH(G24,'Tổng quan'!$B$5:$B$7,0)),"")) -> Người 2 | J24: File .pbix bản 1 | K24: ='Tổng quan'!$E$11+(B24-1)*7 -> 46328 | L24: ='Tổng quan'!$E$11+(C24-1)*7+4 -> 46339 | M24: Đang làm | N24: 30 | O24: 21/10: có hướng dẫn dựng (docs/powerbi-dashboard-v1.md): mô hình, DAX, 5 trang, bảng số đối chiếu. Chưa có file .pbix (cần máy Windows), chưa kiểm tra trong Power BI
A25: 21 | B25: 4 | C25: 5 | D25: Tuần 4–5 | E25: Khai phá dữ liệu | F25: EDA: phân bố mưa theo mùa, tương quan các biến | G25: N3 | H25: =IF(G25="Cả nhóm","Cả nhóm",IFERROR(INDEX('Tổng quan'!$C$5:$C$7,MATCH(G25,'Tổng quan'!$B$5:$B$7,0)),"")) -> Người 3 | J25: Notebook EDA | K25: ='Tổng quan'!$E$11+(B25-1)*7 -> 46328 | L25: ='Tổng quan'!$E$11+(C25-1)*7+4 -> 46339 | M25: Đang làm | N25: 90 | O25: 21/10: notebooks/eda_rain_next24h.ipynb (chạy trên dữ liệu thật, chỉ dùng tập train để chọn biến): mùa vụ mạnh (T8 78%, T12 26%), giờ trong ngày gần như không ảnh hưởng, biến tách tốt nhất: điểm sương, mưa 24h trước, độ ẩm, áp suất. Logic trong scripts/rain_eda.py có test. Do N1/N2 làm thay N3
A26: 22 | B26: 4 | C26: 5 | D26: Tuần 4–5 | E26: Khai phá dữ liệu | F26: Tạo nhãn RainNext24h | G26: N3 | H26: =IF(G26="Cả nhóm","Cả nhóm",IFERROR(INDEX('Tổng quan'!$C$5:$C$7,MATCH(G26,'Tổng quan'!$B$5:$B$7,0)),"")) -> Người 3 | J26: Cột nhãn trong tập huấn luyện | K26: ='Tổng quan'!$E$11+(B26-1)*7 -> 46328 | L26: ='Tổng quan'!$E$11+(C26-1)*7+4 -> 46339 | M26: Đang làm | N26: 95 | O26: 21/10: gold/ml_labels/rain_next24h_labels_v1.parquet + manifest: 700.800 nhãn dùng được (train 560.832 / val 70.080 / test 69.888; Yes 50,9% / 49,4% / 49,0%), 576 mẫu loại ở ranh giới. Test t/t+1/t+24/t+25, thiếu giờ, ranh giới. Do N1/N2 làm thay N3
A27: 23 | B27: 4 | C27: 5 | D27: Tuần 4–5 | E27: Khai phá dữ liệu | F27: Xây đặc trưng: độ trễ, trung bình trượt, biến thiên áp suất 3h/24h, giờ/tháng | G27: N3 | H27: =IF(G27="Cả nhóm","Cả nhóm",IFERROR(INDEX('Tổng quan'!$C$5:$C$7,MATCH(G27,'Tổng quan'!$B$5:$B$7,0)),"")) -> Người 3 | J27: Bộ đặc trưng, không rò rỉ dữ liệu | K27: ='Tổng quan'!$E$11+(B27-1)*7 -> 46328 | L27: ='Tổng quan'!$E$11+(C27-1)*7+4 -> 46339 | M27: Đang làm | N27: 90 | O27: 21/10: gold/ml_features/cart_rain_{train_2016_2023,val_2024,test_2025}_v1.parquet + manifest: 22 đặc trưng chỉ từ Open-Meteo (giá trị tại t, trễ 3/6h, mưa 3/6/12/24h trước, TB 6h, biến thiên áp suất 3h/24h, giờ/tháng địa phương). 700.800 dòng = đúng số nhãn dùng được; thiếu giá trị chỉ ở 24 giờ đầu 2016 (192 dòng). Test chống rò rỉ, thiếu giờ, không lẫn vị trí. Do N1/N2 làm thay N3
A28: 24 | B28: 6 | C28: 7 | D28: Tuần 6–7 | E28: Chất lượng dữ liệu | F28: Bước kiểm tra trong Airflow: đếm dòng, % thiếu, khoảng giá trị hợp lệ | G28: N1 | H28: =IF(G28="Cả nhóm","Cả nhóm",IFERROR(INDEX('Tổng quan'!$C$5:$C$7,MATCH(G28,'Tổng quan'!$B$5:$B$7,0)),"")) -> Người 1 | J28: Task kiểm tra trong DAG | K28: ='Tổng quan'!$E$11+(B28-1)*7 -> 46342 | L28: ='Tổng quan'!$E$11+(C28-1)*7+4 -> 46353 | M28: Chưa bắt đầu | N28: 0
A29: 25 | B29: 6 | C29: 7 | D29: Tuần 6–7 | E29: Orchestration | F29: DAG cập nhật tăng dần (incremental) | G29: N1 | H29: =IF(G29="Cả nhóm","Cả nhóm",IFERROR(INDEX('Tổng quan'!$C$5:$C$7,MATCH(G29,'Tổng quan'!$B$5:$B$7,0)),"")) -> Người 1 | J29: DAG chạy theo lịch | K29: ='Tổng quan'!$E$11+(B29-1)*7 -> 46342 | L29: ='Tổng quan'!$E$11+(C29-1)*7+4 -> 46353 | M29: Chưa bắt đầu | N29: 0
A30: 26 | B30: 6 | C30: 7 | D30: Tuần 6–7 | E30: Data Warehouse | F30: Index và tối ưu truy vấn DW | G30: N1 | H30: =IF(G30="Cả nhóm","Cả nhóm",IFERROR(INDEX('Tổng quan'!$C$5:$C$7,MATCH(G30,'Tổng quan'!$B$5:$B$7,0)),"")) -> Người 1 | I30: N2 | J30: Thời gian truy vấn dashboard chấp nhận được | K30: ='Tổng quan'!$E$11+(B30-1)*7 -> 46342 | L30: ='Tổng quan'!$E$11+(C30-1)*7+4 -> 46353 | M30: Chưa bắt đầu | N30: 0
A31: 27 | B31: 6 | C31: 7 | D31: Tuần 6–7 | E31: BI | F31: Dashboard đầy đủ: bản đồ, so sánh khu vực và nguồn, Roll-up / Drill-down / Slice / Dice | G31: N2 | H31: =IF(G31="Cả nhóm","Cả nhóm",IFERROR(INDEX('Tổng quan'!$C$5:$C$7,MATCH(G31,'Tổng quan'!$B$5:$B$7,0)),"")) -> Người 2 | J31: Dashboard hoàn chỉnh | K31: ='Tổng quan'!$E$11+(B31-1)*7 -> 46342 | L31: ='Tổng quan'!$E$11+(C31-1)*7+4 -> 46353 | M31: Chưa bắt đầu | N31: 0
A32: 28 | B32: 6 | C32: 7 | D32: Tuần 6–7 | E32: Khai phá dữ liệu | F32: Huấn luyện CART, tinh chỉnh max_depth, ccp_alpha, class_weight trên tập 2024 | G32: N3 | H32: =IF(G32="Cả nhóm","Cả nhóm",IFERROR(INDEX('Tổng quan'!$C$5:$C$7,MATCH(G32,'Tổng quan'!$B$5:$B$7,0)),"")) -> Người 3 | J32: Mô hình tốt nhất trên validation | K32: ='Tổng quan'!$E$11+(B32-1)*7 -> 46342 | L32: ='Tổng quan'!$E$11+(C32-1)*7+4 -> 46353 | M32: Đang làm | N32: 90 | O32: 21/10: gold/ml_models/cart_rain_next24h_v1 (model.joblib + report.json). Lưới 120 cấu hình fit trên train 2016-2023, chọn trên validation 2024 theo F1: max_depth=8, min_samples_leaf=50, class_weight=balanced, ccp_alpha=1e-4, 88 lá, ngưỡng xác suất 0,40. Validation: Precision 0,752 / Recall 0,822 / F1 0,786 (mốc dự báo theo hiện trạng F1 0,753). Chưa đọc tập test. Do N1/N2 làm thay N3
A33: 29 | B33: 6 | C33: 7 | D33: Tuần 6–7 | E33: Đánh giá mô hình | F33: Kiểm tra trên tập 2025: confusion matrix, Accuracy, Precision, Recall, F1; chỉnh ngưỡng xác suất | G33: N3 | H33: =IF(G33="Cả nhóm","Cả nhóm",IFERROR(INDEX('Tổng quan'!$C$5:$C$7,MATCH(G33,'Tổng quan'!$B$5:$B$7,0)),"")) -> Người 3 | J33: Bảng chỉ số đánh giá | K33: ='Tổng quan'!$E$11+(B33-1)*7 -> 46342 | L33: ='Tổng quan'!$E$11+(C33-1)*7+4 -> 46353 | M33: Đang làm | N33: 90 | O33: 21/10: đánh giá 1 lần trên test 2025 với model + ngưỡng 0,40 đã chốt từ validation (không chỉnh ngưỡng bằng test). 69.888/69.888 mẫu. TP 27.254 / FP 8.782 / TN 26.840 / FN 7.012; Accuracy 0,774, Precision 0,756, Recall 0,795, F1 0,775 (dự báo theo hiện trạng F1 0,726). Mùa mưa F1 0,835, mùa khô 0,621. gold/ml_models/cart_rain_next24h_v1/test_evaluation.json. Do N1/N2 làm thay N3
A34: 30 | B34: 6 | C34: 7 | D34: Tuần 6–7 | E34: Khai phá dữ liệu | F34: Vẽ và diễn giải cây quyết định, trích luật phân loại | G34: N3 | H34: =IF(G34="Cả nhóm","Cả nhóm",IFERROR(INDEX('Tổng quan'!$C$5:$C$7,MATCH(G34,'Tổng quan'!$B$5:$B$7,0)),"")) -> Người 3 | J34: Hình cây + luật | K34: ='Tổng quan'!$E$11+(B34-1)*7 -> 46342 | L34: ='Tổng quan'!$E$11+(C34-1)*7+4 -> 46353 | M34: Chưa bắt đầu | N34: 0
A35: 31 | B35: 8 | C35: 8 | D35: Tuần 8 | E35: Tích hợp ML | F35: Thiết kế FactWeatherPrediction, DimModel; ghi kết quả dự báo vào DW | G35: N3 | H35: =IF(G35="Cả nhóm","Cả nhóm",IFERROR(INDEX('Tổng quan'!$C$5:$C$7,MATCH(G35,'Tổng quan'!$B$5:$B$7,0)),"")) -> Người 3 | I35: N2 | J35: Bảng dự báo có dữ liệu | K35: ='Tổng quan'!$E$11+(B35-1)*7 -> 46356 | L35: ='Tổng quan'!$E$11+(C35-1)*7+4 -> 46360 | M35: Chưa bắt đầu | N35: 0
A36: 32 | B36: 8 | C36: 8 | D36: Tuần 8 | E36: Orchestration | F36: DAG chấm điểm dự báo | G36: N1 | H36: =IF(G36="Cả nhóm","Cả nhóm",IFERROR(INDEX('Tổng quan'!$C$5:$C$7,MATCH(G36,'Tổng quan'!$B$5:$B$7,0)),"")) -> Người 1 | I36: N3 | J36: DAG dự báo chạy được | K36: ='Tổng quan'!$E$11+(B36-1)*7 -> 46356 | L36: ='Tổng quan'!$E$11+(C36-1)*7+4 -> 46360 | M36: Chưa bắt đầu | N36: 0
A37: 33 | B37: 8 | C37: 8 | D37: Tuần 8 | E37: BI | F37: Trang dashboard dự báo so với thực tế | G37: N2 | H37: =IF(G37="Cả nhóm","Cả nhóm",IFERROR(INDEX('Tổng quan'!$C$5:$C$7,MATCH(G37,'Tổng quan'!$B$5:$B$7,0)),"")) -> Người 2 | I37: N3 | J37: Trang dự báo trong Power BI | K37: ='Tổng quan'!$E$11+(B37-1)*7 -> 46356 | L37: ='Tổng quan'!$E$11+(C37-1)*7+4 -> 46360 | M37: Chưa bắt đầu | N37: 0
A38: 34 | B38: 9 | C38: 9 | D38: Tuần 9 | E38: Kiểm thử | F38: Chạy lại toàn bộ pipeline trên máy sạch, sửa lỗi | G38: N1 | H38: =IF(G38="Cả nhóm","Cả nhóm",IFERROR(INDEX('Tổng quan'!$C$5:$C$7,MATCH(G38,'Tổng quan'!$B$5:$B$7,0)),"")) -> Người 1 | J38: Pipeline chạy từ đầu đến cuối | K38: ='Tổng quan'!$E$11+(B38-1)*7 -> 46363 | L38: ='Tổng quan'!$E$11+(C38-1)*7+4 -> 46367 | M38: Chưa bắt đầu | N38: 0
A39: 35 | B39: 9 | C39: 9 | D39: Tuần 9 | E39: Kiểm thử | F39: Đối chiếu số liệu dashboard với truy vấn SQL | G39: N2 | H39: =IF(G39="Cả nhóm","Cả nhóm",IFERROR(INDEX('Tổng quan'!$C$5:$C$7,MATCH(G39,'Tổng quan'!$B$5:$B$7,0)),"")) -> Người 2 | J39: Biên bản đối chiếu | K39: ='Tổng quan'!$E$11+(B39-1)*7 -> 46363 | L39: ='Tổng quan'!$E$11+(C39-1)*7+4 -> 46367 | M39: Chưa bắt đầu | N39: 0
A40: 36 | B40: 9 | C40: 9 | D40: Tuần 9 | E40: Đánh giá mô hình | F40: Phân tích lỗi mô hình, so sánh các ngưỡng | G40: N3 | H40: =IF(G40="Cả nhóm","Cả nhóm",IFERROR(INDEX('Tổng quan'!$C$5:$C$7,MATCH(G40,'Tổng quan'!$B$5:$B$7,0)),"")) -> Người 3 | J40: Phần phân tích lỗi | K40: ='Tổng quan'!$E$11+(B40-1)*7 -> 46363 | L40: ='Tổng quan'!$E$11+(C40-1)*7+4 -> 46367 | M40: Chưa bắt đầu | N40: 0
A41: 37 | B41: 10 | C41: 10 | D41: Tuần 10 | E41: Báo cáo | F41: Chương: nguồn dữ liệu, Data Lake, ETL | G41: N1 | H41: =IF(G41="Cả nhóm","Cả nhóm",IFERROR(INDEX('Tổng quan'!$C$5:$C$7,MATCH(G41,'Tổng quan'!$B$5:$B$7,0)),"")) -> Người 1 | K41: ='Tổng quan'!$E$11+(B41-1)*7 -> 46370 | L41: ='Tổng quan'!$E$11+(C41-1)*7+4 -> 46374 | M41: Chưa bắt đầu | N41: 0
...

Sheet Vai trò
A1: Phân công vai trò
A3: Hạng mục | B3: Người 1 – Data Engineer | C3: Người 2 – DW & BI | D3: Người 3 – Data Mining
A4: Hạ tầng | B4: Docker Compose (MinIO, Airflow, PostgreSQL), repo Git | C4: Cài đặt và kết nối Power BI với PostgreSQL | D4: Môi trường Python cho ML
A5: Nguồn dữ liệu | B5: Open-Meteo (JSON), Meteostat/NOAA (CSV) → Bronze, Silver | C5: GeoJSON địa giới, gán trạm vào địa điểm | D5: ERA5 (NetCDF, xarray) → Bronze, Silver
A6: ETL | B6: Gộp Silver thành Gold, toàn bộ DAG Airflow, kiểm tra chất lượng | C6: Nạp Gold vào DW (khóa thay thế, các bảng Dim) | D6: DAG chấm điểm dự báo (làm cùng Người 1)
A7: Kho dữ liệu | B7: Index, tối ưu truy vấn | C7: Thiết kế Star Schema, DDL, Dim, Fact, view OLAP | D7: Thiết kế FactWeatherPrediction, DimModel
A8: Phân tích | B8: – | C8: Dashboard: xu hướng, so sánh khu vực và nguồn, bản đồ, Roll-up/Drill-down/Slice/Dice | D8: EDA, tạo nhãn, đặc trưng, CART, đánh giá mô hình
A9: Báo cáo | B9: Chương nguồn dữ liệu, Data Lake, ETL | C9: Chương DW, OLAP, dashboard | D9: Chương khai phá dữ liệu, đánh giá

Sheet Rủi ro
A1: Rủi ro và cách xử lý
A3: Vấn đề | B3: Chi tiết | C3: Cách xử lý | D3: Mã phụ trách | E3: Trạng thái | F3: Ghi chú
A4: ERA5 tải chậm | B4: Cần tài khoản Copernicus CDS; yêu cầu tải xếp hàng có thể mất nhiều giờ đến nhiều ngày. | C4: Đăng ký và gửi yêu cầu ngay tuần 1; chỉ lấy vùng miền Bắc và biến cần dùng; tải theo tháng/năm. | D4: N3 | E4: Đang theo dõi
A5: Đơn vị ERA5 khác hẳn | B5: Nhiệt độ Kelvin, mưa mét, áp suất Pa, gió dạng u/v; ERA5-Land cộng dồn mưa từ 00 UTC. | C5: Đổi đơn vị ở Silver, tính tốc độ/hướng gió từ u/v, khử cộng dồn, lấy ô lưới gần nhất. | D5: N3 | E5: Đang theo dõi
A6: Open-Meteo và ERA5 trùng gốc | B6: API lịch sử Open-Meteo dựng chủ yếu từ dữ liệu tái phân tích ERA5. | C6: Nêu rõ trong báo cáo; dùng như điểm cộng để đối chiếu chéo nguồn. | D6: N1 | E6: Đang theo dõi
A7: Trạm Meteostat/NOAA thưa | B7: Miền Bắc ít trạm, nhiều giờ thiếu; không phải địa điểm nào cũng có trạm. | C7: Gán trạm theo khoảng cách bằng GeoPandas; khóa DimStation cho phép rỗng với nguồn lưới. | D7: N2 | E7: Đang theo dõi
A8: Múi giờ | B8: ERA5, Meteostat dùng UTC; Open-Meteo có thể trả giờ địa phương. | C8: Lưu thống nhất UTC, thêm cột giờ Việt Nam (UTC+7). | D8: N1 | E8: Đang theo dõi
A9: Địa giới hành chính mới | B9: Sáp nhập tỉnh từ 1/7/2025 (vd Hòa Bình nay thuộc Phú Thọ); danh sách địa điểm trộn tên cũ/mới. | C9: Địa điểm = điểm tọa độ; DimLocation lưu cả tỉnh cũ và mới; GeoJSON dùng ranh giới mới. | D9: N2 | E9: Đang theo dõi
A10: Nhãn mưa chưa rõ | B10: Chưa xác định nguồn lấy nhãn và ngưỡng mm. | C10: Chốt sớm: tổng mưa 24h tới ≥ 0,1 mm (hoặc 1 mm), ưu tiên trạm, thiếu thì dùng ERA5. | D10: Cả nhóm | E10: Đang theo dõi
A11: Rò rỉ dữ liệu khi học máy | B11: Đặc trưng vô tình chứa thông tin tương lai. | C11: Mọi đặc trưng chỉ dùng dữ liệu tại hoặc trước thời điểm t; chia tập theo thời gian. | D11: N3 | E11: Đang theo dõi
A12: Mất cân bằng lớp | B12: Mùa khô có rất ít giờ mưa. | C12: class_weight='balanced', chỉnh ngưỡng xác suất trên tập 2024 để tăng Recall. | D12: N3 | E12: Đang theo dõi
A13: Hạ tầng | B13: Airflow trên Docker tốn ~4 GB RAM; Power BI Desktop chỉ chạy trên Windows. | C13: Chuẩn bị ít nhất một máy Windows RAM từ 16 GB. | D13: N1 | E13: Đang theo dõi
